Workbook

Sheet 職種別 (2種)
A1: 期間: 2025-12-01 ~ 2025-12-31
A2: 対象モジュール: カスタムメイドケアサポート、施設360
A3: 対象職種: ホーム長・副ホーム長・看護師・ケアマネ・ケアコン
A4: 2モジュール合計カウント点数化: 0-3count=0点、4-7count=1点、8count以上=2点
A5: # | B5: 本部 | C5: 施設名 | D5: 役職 | E5: 在籍 人数 | F5: カスタムメイドケアサポート | H5: 施設360 | J5: 2種 職種別合計 | K5: ホーム 合計点 | L5: 職種別 点数化 | M5: 職種別 点数化
F6: アクセス数 | G6: アクセス数 /人 | H6: アクセス数 | I6: アクセス数 /人
A7: 1 | B7: 東日本本部 | C7: そんぽの家 苗穂 | D7: ホーム長 | E7: 1 | F7: 12 | G7: 12 | H7: 0 | I7: 0 | J7: 12 | K7: =SUM(M7:M11) -> 6 | L7: 2 | M7: =L7 -> 2 | N7: 1110351100
A8: 2 | B8: =B7 -> 東日本本部 | C8: =C7 -> そんぽの家 苗穂 | D8: 副ホーム長 | E8: 2 | F8: 17 | G8: 8.5 | H8: 0 | I8: 0 | J8: 17 | K8: =K7 -> 6 | L8: 2 | M8: =L8 -> 2 | N8: 1110351100
A9: 3 | B9: =B8 -> 東日本本部 | C9: =C8 -> そんぽの家 苗穂 | D9: ケアマネジャー | E9: 2 | F9: 56 | G9: 28 | H9: 0 | I9: 0 | J9: 56 | K9: =K8 -> 6 | L9: 2 | M9: =L9 -> 2 | N9: 1110351100
A10: 4 | B10: =B9 -> 東日本本部 | C10: =C9 -> そんぽの家 苗穂 | D10: ナーススタッフ | E10: 3 | F10: 0 | G10: 0 | H10: 0 | I10: 0 | J10: 0 | K10: =K9 -> 6 | L10: 0 | M10: =L10 -> 0 | N10: 1110351100
A11: 5 | B11: =B10 -> 東日本本部 | C11: =C10 -> そんぽの家 苗穂 | D11: ケアコンダクター | E11: 1 | F11: 0 | G11: 0 | H11: 0 | I11: 0 | J11: 0 | K11: =K10 -> 6 | L11: 0 | M11: =L11 -> 0 | N11: 1110351100
A12: 6 | B12: 東日本本部 | C12: ラヴィーレ真駒内 | D12: ホーム長 | E12: 1 | F12: 9 | G12: 9 | H12: 0 | I12: 0 | J12: 9 | K12: =SUM(M12:M16) -> 6 | L12: 2 | M12: =L12 -> 2 | N12: 1118201100
A13: 7 | B13: =B12 -> 東日本本部 | C13: =C12 -> ラヴィーレ真駒内 | D13: 副ホーム長 | E13: 1 | F13: 10 | G13: 10 | H13: 1 | I13: 1 | J13: 11 | K13: =K12 -> 6 | L13: 2 | M13: =L13 -> 2 | N13: 1118201100
A14: 8 | B14: =B13 -> 東日本本部 | C14: =C13 -> ラヴィーレ真駒内 | D14: ケアマネジャー | E14: 1 | F14: 16 | G14: 16 | H14: 0 | I14: 0 | J14: 16 | K14: =K13 -> 6 | L14: 2 | M14: =L14 -> 2 | N14: 1118201100
A15: 9 | B15: =B14 -> 東日本本部 | C15: =C14 -> ラヴィーレ真駒内 | D15: ナーススタッフ | E15: 6 | F15: 0 | G15: 0 | H15: 0 | I15: 0 | J15: 0 | K15: =K14 -> 6 | L15: 0 | M15: =L15 -> 0 | N15: 1118201100
A16: 10 | B16: =B15 -> 東日本本部 | C16: =C15 -> ラヴィーレ真駒内 | D16: ケアコンダクター | E16: 1 | F16: 1 | G16: 1 | H16: 0 | I16: 0 | J16: 1 | K16: =K15 -> 6 | L16: 0 | M16: =L16 -> 0 | N16: 1118201100
A17: 11 | B17: 東日本本部 | C17: ラヴィーレ白石南郷 | D17: ホーム長 | E17: 1 | F17: 10 | G17: 10 | H17: 1 | I17: 1 | J17: 11 | K17: =SUM(M17:M21) -> 6 | L17: 2 | M17: =L17 -> 2 | N17: 1118211100
A18: 12 | B18: =B17 -> 東日本本部 | C18: =C17 -> ラヴィーレ白石南郷 | D18: 副ホーム長 | E18: 1 | F18: 0 | G18: 0 | H18: 0 | I18: 0 | J18: 0 | K18: =K17 -> 6 | L18: 0 | M18: =L18 -> 0 | N18: 1118211100
A19: 13 | B19: =B18 -> 東日本本部 | C19: =C18 -> ラヴィーレ白石南郷 | D19: ケアマネジャー | E19: 2 | F19: 39 | G19: 19.5 | H19: 0 | I19: 0 | J19: 39 | K19: =K18 -> 6 | L19: 2 | M19: =L19 -> 2 | N19: 1118211100
A20: 14 | B20: =B19 -> 東日本本部 | C20: =C19 -> ラヴィーレ白石南郷 | D20: ナーススタッフ | E20: 9 | F20: 0 | G20: 0 | H20: 0 | I20: 0 | J20: 0 | K20: =K19 -> 6 | L20: 0 | M20: =L20 -> 0 | N20: 1118211100
A21: 15 | B21: =B20 -> 東日本本部 | C21: =C20 -> ラヴィーレ白石南郷 | D21: ケアコンダクター | E21: 2 | F21: 27 | G21: 13.5 | H21: 0 | I21: 0 | J21: 27 | K21: =K20 -> 6 | L21: 2 | M21: =L21 -> 2 | N21: 1118211100
A22: 16 | B22: 東日本本部 | C22: そんぽの家 仙台岩切 | D22: ホーム長 | E22: 1 | F22: 10 | G22: 10 | H22: 2 | I22: 2 | J22: 12 | K22: =SUM(M22:M26) -> 6 | L22: 2 | M22: =L22 -> 2 | N22: 1410581100
A23: 17 | B23: =B22 -> 東日本本部 | C23: =C22 -> そんぽの家 仙台岩切 | D23: 副ホーム長 | E23: 1 | F23: 26 | G23: 26 | H23: 2 | I23: 2 | J23: 28 | K23: =K22 -> 6 | L23: 2 | M23: =L23 -> 2 | N23: 1410581100
A24: 18 | B24: =B23 -> 東日本本部 | C24: =C23 -> そんぽの家 仙台岩切 | D24: ケアマネジャー | E24: 1 | F24: 23 | G24: 23 | H24: 0 | I24: 0 | J24: 23 | K24: =K23 -> 6 | L24: 2 | M24: =L24 -> 2 | N24: 1410581100
A25: 19 | B25: =B24 -> 東日本本部 | C25: =C24 -> そんぽの家 仙台岩切 | D25: ナーススタッフ | E25: 3 | F25: 0 | G25: 0 | H25: 0 | I25: 0 | J25: 0 | K25: =K24 -> 6 | L25: 0 | M25: =L25 -> 0 | N25: 1410581100
A26: 20 | B26: =B25 -> 東日本本部 | C26: =C25 -> そんぽの家 仙台岩切 | D26: ケアコンダクター | E26: 1 | F26: 0 | G26: 0 | H26: 0 | I26: 0 | J26: 0 | K26: =K25 -> 6 | L26: 0 | M26: =L26 -> 0 | N26: 1410581100
A27: 21 | B27: 東日本本部 | C27: ラヴィーレ仙台東 | D27: ホーム長 | E27: 1 | F27: 1 | G27: 1 | H27: 1 | I27: 1 | J27: 2 | K27: =SUM(M27:M31) -> 4 | L27: 0 | M27: =L27 -> 0 | N27: 1418251100
A28: 22 | B28: =B27 -> 東日本本部 | C28: =C27 -> ラヴィーレ仙台東 | D28: 副ホーム長 | E28: 1 | F28: 5 | G28: 5 | H28: 4 | I28: 4 | J28: 9 | K28: =K27 -> 4 | L28: 2 | M28: =L28 -> 2 | N28: 1418251100
A29: 23 | B29: =B28 -> 東日本本部 | C29: =C28 -> ラヴィーレ仙台東 | D29: ケアマネジャー | E29: 2 | F29: 9 | G29: 4.5 | H29: 0 | I29: 0 | J29: 9 | K29: =K28 -> 4 | L29: 2 | M29: =L29 -> 2 | N29: 1418251100
A30: 24 | B30: =B29 -> 東日本本部 | C30: =C29 -> ラヴィーレ仙台東 | D30: ナーススタッフ | E30: 16 | F30: 2 | G30: 0.1 | H30: 0 | I30: 0 | J30: 2 | K30: =K29 -> 4 | L30: 0 | M30: =L30 -> 0 | N30: 1418251100
A31: 25 | B31: =B30 -> 東日本本部 | C31: =C30 -> ラヴィーレ仙台東 | D31: ケアコンダクター | E31: 4 | F31: 0 | G31: 0 | H31: 0 | I31: 0 | J31: 0 | K31: =K30 -> 4 | L31: 0 | M31: =L31 -> 0 | N31: 1418251100
A32: 26 | B32: 東日本本部 | C32: ラヴィーレ泉パークタウン朝日 | D32: ホーム長 | E32: 1 | F32: 5 | G32: 5 | H32: 3 | I32: 3 | J32: 8 | K32: =SUM(M32:M36) -> 10 | L32: 2 | M32: =L32 -> 2 | N32: 1418431100
A33: 27 | B33: =B32 -> 東日本本部 | C33: =C32 -> ラヴィーレ泉パークタウン朝日 | D33: 副ホーム長 | E33: 1 | F33: 26 | G33: 26 | H33: 3 | I33: 3 | J33: 29 | K33: =K32 -> 10 | L33: 2 | M33: =L33 -> 2 | N33: 1418431100
A34: 28 | B34: =B33 -> 東日本本部 | C34: =C33 -> ラヴィーレ泉パークタウン朝日 | D34: ケアマネジャー | E34: 1 | F34: 41 | G34: 41 | H34: 0 | I34: 0 | J34: 41 | K34: =K33 -> 10 | L34: 2 | M34: =L34 -> 2 | N34: 1418431100
A35: 29 | B35: =B34 -> 東日本本部 | C35: =C34 -> ラヴィーレ泉パークタウン朝日 | D35: ナーススタッフ | E35: 2 | F35: 9 | G35: 4.5 | H35: 0 | I35: 0 | J35: 9 | K35: =K34 -> 10 | L35: 2 | M35: =L35 -> 2 | N35: 1418431100
A36: 30 | B36: =B35 -> 東日本本部 | C36: =C35 -> ラヴィーレ泉パークタウン朝日 | D36: ケアコンダクター | E36: 1 | F36: 9 | G36: 9 | H36: 0 | I36: 0 | J36: 9 | K36: =K35 -> 10 | L36: 2 | M36: =L36 -> 2 | N36: 1418431100
A37: 31 | B37: 東京本部 | C37: そんぽの家 柴又 | D37: ホーム長 | E37: 1 | F37: 13 | G37: 13 | H37: 2 | I37: 2 | J37: 15 | K37: =SUM(M37:M41) -> 10 | L37: 2 | M37: =L37 -> 2 | N37: 2311161100
A38: 32 | B38: =B37 -> 東京本部 | C38: =C37 -> そんぽの家 柴又 | D38: 副ホーム長 | E38: 1 | F38: 18 | G38: 18 | H38: 16 | I38: 16 | J38: 34 | K38: =K37 -> 10 | L38: 2 | M38: =L38 -> 2 | N38: 2311161100
A39: 33 | B39: =B38 -> 東京本部 | C39: =C38 -> そんぽの家 柴又 | D39: ケアマネジャー | E39: 2 | F39: 68 | G39: 34 | H39: 0 | I39: 0 | J39: 68 | K39: =K38 -> 10 | L39: 2 | M39: =L39 -> 2 | N39: 2311161100
A40: 34 | B40: =B39 -> 東京本部 | C40: =C39 -> そんぽの家 柴又 | D40: ナーススタッフ | E40: 3 | F40: 8 | G40: 2.7 | H40: 0 | I40: 0 | J40: 8 | K40: =K39 -> 10 | L40: 2 | M40: =L40 -> 2 | N40: 2311161100
...

Sheet 職種別 (NC)
A1: 期間: 2025-12-01 ~ 2025-12-31
A2: 対象モジュール: NCコールモニター
A3: 対象職種: ホーム長・副ホーム長・看護師・ケアマネ・ケアコン
A4: 合計カウント点数化: 0-5count=0点、6-10count=1点、11-15count＝2点、16count以上=3点 ※ナースコールの点数化は職種全体の合計点で評価します。
A5: # | B5: 本部 | C5: 施設名 | D5: 役職 | E5: 在籍 人数 | F5: NCコールモニター | H5: 職種別合計 | I5: ホーム 点数化 | J5: 職種別 点数化 | K5: 総計 アクセス数
F6: アクセス数 | G6: アクセス数 /人
A7: 1 | B7: 東日本本部 | C7: そんぽの家 苗穂 | D7: ホーム長 | E7: 1 | F7: 1 | G7: 1 | H7: =F7 -> 1 | I7: {=IF(J7="-","-",_xlfn.IFS(K7<=5,0,K7<=10,1,K7<=15,2,K7>=16,3))} -> 0 | J7: {=IFERROR(IF(_xlfn.XLOOKUP(L7,NC導入施設!B:B,NC導入施設!E:E)=0,_xlfn.IFS(H7<=5,0,H7<=10,1,H7<=15,2,H7>=16,3),"Null"),"-")} -> 0 | K7: =IFERROR(SUM(H7:H11),"-") -> 2 | L7: 1110351100
A8: 2 | B8: =B7 -> 東日本本部 | C8: =C7 -> そんぽの家 苗穂 | D8: 副ホーム長 | E8: 2 | F8: 0 | G8: 0 | H8: =F8 -> 0 | J8: {=IFERROR(IF(_xlfn.XLOOKUP(L8,NC導入施設!B:B,NC導入施設!E:E)=0,_xlfn.IFS(H8<=5,0,H8<=10,1,H8<=15,2,H8>=16,3),"Null"),"-")} -> 0 | L8: 1110351100
A9: 3 | B9: =B8 -> 東日本本部 | C9: =C8 -> そんぽの家 苗穂 | D9: ケアマネジャー | E9: 2 | F9: 1 | G9: 0.5 | H9: =F9 -> 1 | J9: {=IFERROR(IF(_xlfn.XLOOKUP(L9,NC導入施設!B:B,NC導入施設!E:E)=0,_xlfn.IFS(H9<=5,0,H9<=10,1,H9<=15,2,H9>=16,3),"Null"),"-")} -> 0 | L9: 1110351100
A10: 4 | B10: =B9 -> 東日本本部 | C10: =C9 -> そんぽの家 苗穂 | D10: ナーススタッフ | E10: 3 | F10: 0 | G10: 0 | H10: =F10 -> 0 | J10: {=IFERROR(IF(_xlfn.XLOOKUP(L10,NC導入施設!B:B,NC導入施設!E:E)=0,_xlfn.IFS(H10<=5,0,H10<=10,1,H10<=15,2,H10>=16,3),"Null"),"-")} -> 0 | L10: 1110351100
A11: 5 | B11: =B10 -> 東日本本部 | C11: =C10 -> そんぽの家 苗穂 | D11: ケアコンダクター | E11: 1 | F11: 0 | G11: 0 | H11: =F11 -> 0 | J11: {=IFERROR(IF(_xlfn.XLOOKUP(L11,NC導入施設!B:B,NC導入施設!E:E)=0,_xlfn.IFS(H11<=5,0,H11<=10,1,H11<=15,2,H11>=16,3),"Null"),"-")} -> 0 | L11: 1110351100
A12: 6 | B12: 東日本本部 | C12: ラヴィーレ真駒内 | D12: ホーム長 | E12: 1 | F12: 0 | G12: 0 | H12: =F12 -> 0 | I12: {=IF(J12="-","-",_xlfn.IFS(K12<=5,0,K12<=10,1,K12<=15,2,K12>=16,3))} -> - | J12: {=IFERROR(IF(_xlfn.XLOOKUP(L12,NC導入施設!B:B,NC導入施設!E:E)=0,_xlfn.IFS(H12<=5,0,H12<=10,1,H12<=15,2,H12>=16,3),"Null"),"-")} -> - | K12: =IFERROR(SUM(H12:H16),"-") -> 1 | L12: 1118201100
A13: 7 | B13: =B12 -> 東日本本部 | C13: =C12 -> ラヴィーレ真駒内 | D13: 副ホーム長 | E13: 1 | F13: 1 | G13: 1 | H13: =F13 -> 1 | J13: {=IFERROR(IF(_xlfn.XLOOKUP(L13,NC導入施設!B:B,NC導入施設!E:E)=0,_xlfn.IFS(H13<=5,0,H13<=10,1,H13<=15,2,H13>=16,3),"Null"),"-")} -> - | L13: 1118201100
A14: 8 | B14: =B13 -> 東日本本部 | C14: =C13 -> ラヴィーレ真駒内 | D14: ケアマネジャー | E14: 1 | F14: 0 | G14: 0 | H14: =F14 -> 0 | J14: {=IFERROR(IF(_xlfn.XLOOKUP(L14,NC導入施設!B:B,NC導入施設!E:E)=0,_xlfn.IFS(H14<=5,0,H14<=10,1,H14<=15,2,H14>=16,3),"Null"),"-")} -> - | L14: 1118201100
A15: 9 | B15: =B14 -> 東日本本部 | C15: =C14 -> ラヴィーレ真駒内 | D15: ナーススタッフ | E15: 6 | F15: 0 | G15: 0 | H15: =F15 -> 0 | J15: {=IFERROR(IF(_xlfn.XLOOKUP(L15,NC導入施設!B:B,NC導入施設!E:E)=0,_xlfn.IFS(H15<=5,0,H15<=10,1,H15<=15,2,H15>=16,3),"Null"),"-")} -> - | L15: 1118201100
A16: 10 | B16: =B15 -> 東日本本部 | C16: =C15 -> ラヴィーレ真駒内 | D16: ケアコンダクター | E16: 1 | F16: 0 | G16: 0 | H16: =F16 -> 0 | J16: {=IFERROR(IF(_xlfn.XLOOKUP(L16,NC導入施設!B:B,NC導入施設!E:E)=0,_xlfn.IFS(H16<=5,0,H16<=10,1,H16<=15,2,H16>=16,3),"Null"),"-")} -> - | L16: 1118201100
A17: 11 | B17: 東日本本部 | C17: ラヴィーレ白石南郷 | D17: ホーム長 | E17: 1 | F17: 0 | G17: 0 | H17: =F17 -> 0 | I17: {=IF(J17="-","-",_xlfn.IFS(K17<=5,0,K17<=10,1,K17<=15,2,K17>=16,3))} -> - | J17: {=IFERROR(IF(_xlfn.XLOOKUP(L17,NC導入施設!B:B,NC導入施設!E:E)=0,_xlfn.IFS(H17<=5,0,H17<=10,1,H17<=15,2,H17>=16,3),"Null"),"-")} -> - | K17: =IFERROR(SUM(H17:H21),"-") -> 2 | L17: 1118211100
A18: 12 | B18: =B17 -> 東日本本部 | C18: =C17 -> ラヴィーレ白石南郷 | D18: 副ホーム長 | E18: 1 | F18: 0 | G18: 0 | H18: =F18 -> 0 | J18: {=IFERROR(IF(_xlfn.XLOOKUP(L18,NC導入施設!B:B,NC導入施設!E:E)=0,_xlfn.IFS(H18<=5,0,H18<=10,1,H18<=15,2,H18>=16,3),"Null"),"-")} -> - | L18: 1118211100
A19: 13 | B19: =B18 -> 東日本本部 | C19: =C18 -> ラヴィーレ白石南郷 | D19: ケアマネジャー | E19: 2 | F19: 1 | G19: 0.5 | H19: =F19 -> 1 | J19: {=IFERROR(IF(_xlfn.XLOOKUP(L19,NC導入施設!B:B,NC導入施設!E:E)=0,_xlfn.IFS(H19<=5,0,H19<=10,1,H19<=15,2,H19>=16,3),"Null"),"-")} -> - | L19: 1118211100
A20: 14 | B20: =B19 -> 東日本本部 | C20: =C19 -> ラヴィーレ白石南郷 | D20: ナーススタッフ | E20: 9 | F20: 0 | G20: 0 | H20: =F20 -> 0 | J20: {=IFERROR(IF(_xlfn.XLOOKUP(L20,NC導入施設!B:B,NC導入施設!E:E)=0,_xlfn.IFS(H20<=5,0,H20<=10,1,H20<=15,2,H20>=16,3),"Null"),"-")} -> - | L20: 1118211100
A21: 15 | B21: =B20 -> 東日本本部 | C21: =C20 -> ラヴィーレ白石南郷 | D21: ケアコンダクター | E21: 2 | F21: 1 | G21: 0.5 | H21: =F21 -> 1 | J21: {=IFERROR(IF(_xlfn.XLOOKUP(L21,NC導入施設!B:B,NC導入施設!E:E)=0,_xlfn.IFS(H21<=5,0,H21<=10,1,H21<=15,2,H21>=16,3),"Null"),"-")} -> - | L21: 1118211100
A22: 16 | B22: 東日本本部 | C22: そんぽの家 仙台岩切 | D22: ホーム長 | E22: 1 | F22: 12 | G22: 12 | H22: =F22 -> 12 | I22: {=IF(J22="-","-",_xlfn.IFS(K22<=5,0,K22<=10,1,K22<=15,2,K22>=16,3))} -> 3 | J22: {=IFERROR(IF(_xlfn.XLOOKUP(L22,NC導入施設!B:B,NC導入施設!E:E)=0,_xlfn.IFS(H22<=5,0,H22<=10,1,H22<=15,2,H22>=16,3),"Null"),"-")} -> 2 | K22: =IFERROR(SUM(H22:H26),"-") -> 31 | L22: 1410581100
A23: 17 | B23: =B22 -> 東日本本部 | C23: =C22 -> そんぽの家 仙台岩切 | D23: 副ホーム長 | E23: 1 | F23: 4 | G23: 4 | H23: =F23 -> 4 | J23: {=IFERROR(IF(_xlfn.XLOOKUP(L23,NC導入施設!B:B,NC導入施設!E:E)=0,_xlfn.IFS(H23<=5,0,H23<=10,1,H23<=15,2,H23>=16,3),"Null"),"-")} -> 0 | L23: 1410581100
A24: 18 | B24: =B23 -> 東日本本部 | C24: =C23 -> そんぽの家 仙台岩切 | D24: ケアマネジャー | E24: 1 | F24: 15 | G24: 15 | H24: =F24 -> 15 | J24: {=IFERROR(IF(_xlfn.XLOOKUP(L24,NC導入施設!B:B,NC導入施設!E:E)=0,_xlfn.IFS(H24<=5,0,H24<=10,1,H24<=15,2,H24>=16,3),"Null"),"-")} -> 2 | L24: 1410581100
A25: 19 | B25: =B24 -> 東日本本部 | C25: =C24 -> そんぽの家 仙台岩切 | D25: ナーススタッフ | E25: 3 | F25: 0 | G25: 0 | H25: =F25 -> 0 | J25: {=IFERROR(IF(_xlfn.XLOOKUP(L25,NC導入施設!B:B,NC導入施設!E:E)=0,_xlfn.IFS(H25<=5,0,H25<=10,1,H25<=15,2,H25>=16,3),"Null"),"-")} -> 0 | L25: 1410581100
A26: 20 | B26: =B25 -> 東日本本部 | C26: =C25 -> そんぽの家 仙台岩切 | D26: ケアコンダクター | E26: 1 | F26: 0 | G26: 0 | H26: =F26 -> 0 | J26: {=IFERROR(IF(_xlfn.XLOOKUP(L26,NC導入施設!B:B,NC導入施設!E:E)=0,_xlfn.IFS(H26<=5,0,H26<=10,1,H26<=15,2,H26>=16,3),"Null"),"-")} -> 0 | L26: 1410581100
A27: 21 | B27: 東日本本部 | C27: ラヴィーレ仙台東 | D27: ホーム長 | E27: 1 | F27: 0 | G27: 0 | H27: =F27 -> 0 | I27: {=IF(J27="-","-",_xlfn.IFS(K27<=5,0,K27<=10,1,K27<=15,2,K27>=16,3))} -> - | J27: {=IFERROR(IF(_xlfn.XLOOKUP(L27,NC導入施設!B:B,NC導入施設!E:E)=0,_xlfn.IFS(H27<=5,0,H27<=10,1,H27<=15,2,H27>=16,3),"Null"),"-")} -> - | K27: =IFERROR(SUM(H27:H31),"-") -> 7 | L27: 1418251100
A28: 22 | B28: =B27 -> 東日本本部 | C28: =C27 -> ラヴィーレ仙台東 | D28: 副ホーム長 | E28: 1 | F28: 4 | G28: 4 | H28: =F28 -> 4 | J28: {=IFERROR(IF(_xlfn.XLOOKUP(L28,NC導入施設!B:B,NC導入施設!E:E)=0,_xlfn.IFS(H28<=5,0,H28<=10,1,H28<=15,2,H28>=16,3),"Null"),"-")} -> - | L28: 1418251100
A29: 23 | B29: =B28 -> 東日本本部 | C29: =C28 -> ラヴィーレ仙台東 | D29: ケアマネジャー | E29: 2 | F29: 3 | G29: 1.5 | H29: =F29 -> 3 | J29: {=IFERROR(IF(_xlfn.XLOOKUP(L29,NC導入施設!B:B,NC導入施設!E:E)=0,_xlfn.IFS(H29<=5,0,H29<=10,1,H29<=15,2,H29>=16,3),"Null"),"-")} -> - | L29: 1418251100
A30: 24 | B30: =B29 -> 東日本本部 | C30: =C29 -> ラヴィーレ仙台東 | D30: ナーススタッフ | E30: 16 | F30: 0 | G30: 0 | H30: =F30 -> 0 | J30: {=IFERROR(IF(_xlfn.XLOOKUP(L30,NC導入施設!B:B,NC導入施設!E:E)=0,_xlfn.IFS(H30<=5,0,H30<=10,1,H30<=15,2,H30>=16,3),"Null"),"-")} -> - | L30: 1418251100
A31: 25 | B31: =B30 -> 東日本本部 | C31: =C30 -> ラヴィーレ仙台東 | D31: ケアコンダクター | E31: 4 | F31: 0 | G31: 0 | H31: =F31 -> 0 | J31: {=IFERROR(IF(_xlfn.XLOOKUP(L31,NC導入施設!B:B,NC導入施設!E:E)=0,_xlfn.IFS(H31<=5,0,H31<=10,1,H31<=15,2,H31>=16,3),"Null"),"-")} -> - | L31: 1418251100
A32: 26 | B32: 東日本本部 | C32: ラヴィーレ泉パークタウン朝日 | D32: ホーム長 | E32: 1 | F32: 3 | G32: 3 | H32: =F32 -> 3 | I32: {=IF(J32="-","-",_xlfn.IFS(K32<=5,0,K32<=10,1,K32<=15,2,K32>=16,3))} -> 3 | J32: {=IFERROR(IF(_xlfn.XLOOKUP(L32,NC導入施設!B:B,NC導入施設!E:E)=0,_xlfn.IFS(H32<=5,0,H32<=10,1,H32<=15,2,H32>=16,3),"Null"),"-")} -> 0 | K32: =IFERROR(SUM(H32:H36),"-") -> 31 | L32: 1418431100
A33: 27 | B33: =B32 -> 東日本本部 | C33: =C32 -> ラヴィーレ泉パークタウン朝日 | D33: 副ホーム長 | E33: 1 | F33: 25 | G33: 25 | H33: =F33 -> 25 | J33: {=IFERROR(IF(_xlfn.XLOOKUP(L33,NC導入施設!B:B,NC導入施設!E:E)=0,_xlfn.IFS(H33<=5,0,H33<=10,1,H33<=15,2,H33>=16,3),"Null"),"-")} -> 3 | L33: 1418431100
A34: 28 | B34: =B33 -> 東日本本部 | C34: =C33 -> ラヴィーレ泉パークタウン朝日 | D34: ケアマネジャー | E34: 1 | F34: 2 | G34: 2 | H34: =F34 -> 2 | J34: {=IFERROR(IF(_xlfn.XLOOKUP(L34,NC導入施設!B:B,NC導入施設!E:E)=0,_xlfn.IFS(H34<=5,0,H34<=10,1,H34<=15,2,H34>=16,3),"Null"),"-")} -> 0 | L34: 1418431100
A35: 29 | B35: =B34 -> 東日本本部 | C35: =C34 -> ラヴィーレ泉パークタウン朝日 | D35: ナーススタッフ | E35: 2 | F35: 1 | G35: 0.5 | H35: =F35 -> 1 | J35: {=IFERROR(IF(_xlfn.XLOOKUP(L35,NC導入施設!B:B,NC導入施設!E:E)=0,_xlfn.IFS(H35<=5,0,H35<=10,1,H35<=15,2,H35>=16,3),"Null"),"-")} -> 0 | L35: 1418431100
A36: 30 | B36: =B35 -> 東日本本部 | C36: =C35 -> ラヴィーレ泉パークタウン朝日 | D36: ケアコンダクター | E36: 1 | F36: 0 | G36: 0 | H36: =F36 -> 0 | J36: {=IFERROR(IF(_xlfn.XLOOKUP(L36,NC導入施設!B:B,NC導入施設!E:E)=0,_xlfn.IFS(H36<=5,0,H36<=10,1,H36<=15,2,H36>=16,3),"Null"),"-")} -> 0 | L36: 1418431100
A37: 31 | B37: 東京本部 | C37: そんぽの家 柴又 | D37: ホーム長 | E37: 1 | F37: 2 | G37: 2 | H37: =F37 -> 2 | I37: {=IF(J37="-","-",_xlfn.IFS(K37<=5,0,K37<=10,1,K37<=15,2,K37>=16,3))} -> 3 | J37: {=IFERROR(IF(_xlfn.XLOOKUP(L37,NC導入施設!B:B,NC導入施設!E:E)=0,_xlfn.IFS(H37<=5,0,H37<=10,1,H37<=15,2,H37>=16,3),"Null"),"-")} -> 0 | K37: =IFERROR(SUM(H37:H41),"-") -> 65 | L37: 2311161100
A38: 32 | B38: =B37 -> 東京本部 | C38: =C37 -> そんぽの家 柴又 | D38: 副ホーム長 | E38: 1 | F38: 17 | G38: 17 | H38: =F38 -> 17 | J38: {=IFERROR(IF(_xlfn.XLOOKUP(L38,NC導入施設!B:B,NC導入施設!E:E)=0,_xlfn.IFS(H38<=5,0,H38<=10,1,H38<=15,2,H38>=16,3),"Null"),"-")} -> 3 | L38: 2311161100
A39: 33 | B39: =B38 -> 東京本部 | C39: =C38 -> そんぽの家 柴又 | D39: ケアマネジャー | E39: 2 | F39: 23 | G39: 11.5 | H39: =F39 -> 23 | J39: {=IFERROR(IF(_xlfn.XLOOKUP(L39,NC導入施設!B:B,NC導入施設!E:E)=0,_xlfn.IFS(H39<=5,0,H39<=10,1,H39<=15,2,H39>=16,3),"Null"),"-")} -> 3 | L39: 2311161100
A40: 34 | B40: =B39 -> 東京本部 | C40: =C39 -> そんぽの家 柴又 | D40: ナーススタッフ | E40: 3 | F40: 8 | G40: 2.7 | H40: =F40 -> 8 | J40: {=IFERROR(IF(_xlfn.XLOOKUP(L40,NC導入施設!B:B,NC導入施設!E:E)=0,_xlfn.IFS(H40<=5,0,H40<=10,1,H40<=15,2,H40>=16,3),"Null"),"-")} -> 1 | L40: 2311161100
...

Sheet ホーム合計
A1: 本部 | B1: 施設名 | C1: 合計 点数化
A2: 東日本本部 | B2: そんぽの家 苗穂 | C2: =_xlfn.XLOOKUP(B2,'職種別 (2種)'!C:C,'職種別 (2種)'!K:K) -> 6
A3: 東日本本部 | B3: ラヴィーレ真駒内 | C3: =_xlfn.XLOOKUP(B3,'職種別 (2種)'!C:C,'職種別 (2種)'!K:K) -> 6
A4: 東日本本部 | B4: ラヴィーレ白石南郷 | C4: =_xlfn.XLOOKUP(B4,'職種別 (2種)'!C:C,'職種別 (2種)'!K:K) -> 6
A5: 東日本本部 | B5: そんぽの家 仙台岩切 | C5: =_xlfn.XLOOKUP(B5,'職種別 (2種)'!C:C,'職種別 (2種)'!K:K) -> 6
A6: 東日本本部 | B6: ラヴィーレ仙台東 | C6: =_xlfn.XLOOKUP(B6,'職種別 (2種)'!C:C,'職種別 (2種)'!K:K) -> 4
A7: 東日本本部 | B7: ラヴィーレ泉パークタウン朝日 | C7: =_xlfn.XLOOKUP(B7,'職種別 (2種)'!C:C,'職種別 (2種)'!K:K) -> 10
A8: 東京本部 | B8: そんぽの家 柴又 | C8: =_xlfn.XLOOKUP(B8,'職種別 (2種)'!C:C,'職種別 (2種)'!K:K) -> 10
A9: 東京本部 | B9: ラヴィーレ一之江 | C9: =_xlfn.XLOOKUP(B9,'職種別 (2種)'!C:C,'職種別 (2種)'!K:K) -> 8
A10: 東京本部 | B10: ラヴィーレ船堀 | C10: =_xlfn.XLOOKUP(B10,'職種別 (2種)'!C:C,'職種別 (2種)'!K:K) -> 7
A11: 東京本部 | B11: そんぽの家 葛西 | C11: =_xlfn.XLOOKUP(B11,'職種別 (2種)'!C:C,'職種別 (2種)'!K:K) -> 4
A12: 東京本部 | B12: そんぽの家 錦糸町 | C12: =_xlfn.XLOOKUP(B12,'職種別 (2種)'!C:C,'職種別 (2種)'!K:K) -> 5
A13: 東京本部 | B13: そんぽの家 東砂 | C13: =_xlfn.XLOOKUP(B13,'職種別 (2種)'!C:C,'職種別 (2種)'!K:K) -> 3
... A291: 西日本第二本部 | B291: そんぽの家 清水麻生田 | C291: =_xlfn.XLOOKUP(B291,'職種別 (2種)'!C:C,'職種別 (2種)'!K:K) -> 6

Sheet NC導入施設
B1: facility_id | C1: granular_permissions | D1: granular_permissions_array
A2: 1 | B2: 3716691200 | C2: そんぽの家 なんば | D2: 3716691200 | G2: https://sompo.palantirfoundry.com/workspace/dataset/preview/ri.foundry.main.dataset.75349aea-6aa0-4e5e-a3b8-58023e0db66b/master
A3: =A2+1 -> 2 | B3: 2114001200 | C3: そんぽの家 大宮見沼 | D3: 2114001200
A4: =A3+1 -> 3 | B4: 3716701200 | C4: そんぽの家 鶴見緑地 | D4: 3716701200
A5: =A4+1 -> 4 | B5: 2311761100 | C5: そんぽの家 経堂 | D5: 2311761100
A6: =A5+1 -> 5 | B6: 2313141100 | C6: そんぽの家 八坂 | D6: 2313141100
A7: =A6+1 -> 6 | B7: 2114071200 | C7: そんぽの家 大宮 | D7: 2114071200
A8: =A7+1 -> 7 | B8: 3817101200 | C8: そんぽの家 伊丹荒牧 | D8: 3817101200
A9: =A8+1 -> 8 | B9: 4317381200 | C9: そんぽの家 岡山平田 | D9: 4317381200
A10: =A9+1 -> 9 | B10: 3716811200 | C10: そんぽの家 加島駅前 | D10: 3716811200
A11: =A10+1 -> 10 | B11: 3716891200 | C11: そんぽの家 北加賀屋 | D11: 3716891200
A12: =A11+1 -> 11 | B12: 2312551100 | C12: そんぽの家 高円寺 | D12: 2312551100
A13: =A12+1 -> 12 | B13: 3716771200 | C13: そんぽの家 住道 | D13: 3716771200
A14: =A13+1 -> 13 | B14: 2114131200 | C14: そんぽの家 越谷 | D14: 2114131200
... A277: =A276+1 -> 276 | B277: 2414991100 | C277: ＳＯＭＰＯケア ラヴィーレ川崎 | D277: 2414991100
